2025-05-14 16:01:33,224 INFO    MainThread:1774956 [wandb_setup.py:_flush():70] Current SDK version is 0.19.11
2025-05-14 16:01:33,225 INFO    MainThread:1774956 [wandb_setup.py:_flush():70] Configure stats pid to 1774956
2025-05-14 16:01:33,225 INFO    MainThread:1774956 [wandb_setup.py:_flush():70] Loading settings from /nfs/homes/sdreyer/.config/wandb/settings
2025-05-14 16:01:33,225 INFO    MainThread:1774956 [wandb_setup.py:_flush():70] Loading settings from /nfs/homes/sdreyer/Digit-Classification-Pytorch/wandb/settings
2025-05-14 16:01:33,226 INFO    MainThread:1774956 [wandb_setup.py:_flush():70] Loading settings from environment variables
2025-05-14 16:01:33,226 INFO    MainThread:1774956 [wandb_init.py:setup_run_log_directory():724] Logging user logs to /nfs/homes/sdreyer/Digit-Classification-Pytorch/wandb/run-20250514_160133-clu7ddqe/logs/debug.log
2025-05-14 16:01:33,226 INFO    MainThread:1774956 [wandb_init.py:setup_run_log_directory():725] Logging internal logs to /nfs/homes/sdreyer/Digit-Classification-Pytorch/wandb/run-20250514_160133-clu7ddqe/logs/debug-internal.log
2025-05-14 16:01:33,226 INFO    MainThread:1774956 [wandb_init.py:init():852] calling init triggers
2025-05-14 16:01:33,227 INFO    MainThread:1774956 [wandb_init.py:init():857] wandb.init called with sweep_config: {}
config: {'_wandb': {}}
2025-05-14 16:01:33,227 INFO    MainThread:1774956 [wandb_init.py:init():893] starting backend
2025-05-14 16:01:33,227 INFO    MainThread:1774956 [wandb_init.py:init():897] sending inform_init request
2025-05-14 16:01:33,236 INFO    MainThread:1774956 [backend.py:_multiprocessing_setup():101] multiprocessing start_methods=fork,spawn,forkserver, using: spawn
2025-05-14 16:01:33,236 INFO    MainThread:1774956 [wandb_init.py:init():907] backend started and connected
2025-05-14 16:01:33,237 INFO    MainThread:1774956 [wandb_init.py:init():1005] updated telemetry
2025-05-14 16:01:33,252 INFO    MainThread:1774956 [wandb_init.py:init():1029] communicating run to backend with 90.0 second timeout
2025-05-14 16:01:33,998 INFO    MainThread:1774956 [wandb_init.py:init():1104] starting run threads in backend
2025-05-14 16:01:34,070 INFO    MainThread:1774956 [wandb_run.py:_console_start():2573] atexit reg
2025-05-14 16:01:34,070 INFO    MainThread:1774956 [wandb_run.py:_redirect():2421] redirect: wrap_raw
2025-05-14 16:01:34,071 INFO    MainThread:1774956 [wandb_run.py:_redirect():2490] Wrapping output streams.
2025-05-14 16:01:34,071 INFO    MainThread:1774956 [wandb_run.py:_redirect():2513] Redirects installed.
2025-05-14 16:01:34,074 INFO    MainThread:1774956 [wandb_init.py:init():1150] run started, returning control to user process
2025-05-14 16:01:34,518 INFO    MainThread:1774956 [pyagent.py:run():322] [no run ID] Starting sweep agent: entity=None, project=None, count=None
2025-05-14 16:01:35,312 INFO    MsgRouterThr:1774956 [mailbox.py:close():129] [no run ID] Closing mailbox, abandoning 1 handles.
2025-05-14 16:01:36,229 ERROR   Thread-4  :1774956 [redirect.py:_on_write():664] [no run ID] error in stderr callback
Traceback (most recent call last):
  File "/nfs/homes/sdreyer/.local/lib/python3.9/site-packages/wandb/sdk/lib/redirect.py", line 662, in _on_write
    cb(written_data)
  File "/nfs/homes/sdreyer/.local/lib/python3.9/site-packages/wandb/sdk/wandb_run.py", line 2500, in <lambda>
    lambda data: self._console_raw_callback("stderr", data),
  File "/nfs/homes/sdreyer/.local/lib/python3.9/site-packages/wandb/sdk/wandb_run.py", line 406, in wrapper
    return func(self, *args, **kwargs)
  File "/nfs/homes/sdreyer/.local/lib/python3.9/site-packages/wandb/sdk/wandb_run.py", line 464, in wrapper_fn
    return func(self, *args, **kwargs)
  File "/nfs/homes/sdreyer/.local/lib/python3.9/site-packages/wandb/sdk/wandb_run.py", line 1639, in _console_raw_callback
    self._backend.interface.publish_output_raw(name, data)
  File "/nfs/homes/sdreyer/.local/lib/python3.9/site-packages/wandb/sdk/interface/interface.py", line 762, in publish_output_raw
    self._publish_output_raw(o)
  File "/nfs/homes/sdreyer/.local/lib/python3.9/site-packages/wandb/sdk/interface/interface_shared.py", line 38, in _publish_output_raw
    self._publish(rec)
  File "/nfs/homes/sdreyer/.local/lib/python3.9/site-packages/wandb/sdk/interface/interface_sock.py", line 39, in _publish
    self._sock_client.send_record_publish(record)
  File "/nfs/homes/sdreyer/.local/lib/python3.9/site-packages/wandb/sdk/lib/sock_client.py", line 174, in send_record_publish
    self.send_server_request(server_req)
  File "/nfs/homes/sdreyer/.local/lib/python3.9/site-packages/wandb/sdk/lib/sock_client.py", line 154, in send_server_request
    self._send_message(msg)
  File "/nfs/homes/sdreyer/.local/lib/python3.9/site-packages/wandb/sdk/lib/sock_client.py", line 151, in _send_message
    self._sendall_with_error_handle(header + data)
  File "/nfs/homes/sdreyer/.local/lib/python3.9/site-packages/wandb/sdk/lib/sock_client.py", line 130, in _sendall_with_error_handle
    sent = self._sock.send(data)
BrokenPipeError: [Errno 32] Broken pipe
2025-05-14 16:01:36,233 ERROR   Thread-4  :1774956 [redirect.py:_on_write():664] [no run ID] error in stderr callback
Traceback (most recent call last):
  File "/nfs/homes/sdreyer/.local/lib/python3.9/site-packages/wandb/sdk/lib/redirect.py", line 662, in _on_write
    cb(written_data)
  File "/nfs/homes/sdreyer/.local/lib/python3.9/site-packages/wandb/sdk/wandb_run.py", line 2500, in <lambda>
    lambda data: self._console_raw_callback("stderr", data),
  File "/nfs/homes/sdreyer/.local/lib/python3.9/site-packages/wandb/sdk/wandb_run.py", line 406, in wrapper
    return func(self, *args, **kwargs)
  File "/nfs/homes/sdreyer/.local/lib/python3.9/site-packages/wandb/sdk/wandb_run.py", line 464, in wrapper_fn
    return func(self, *args, **kwargs)
  File "/nfs/homes/sdreyer/.local/lib/python3.9/site-packages/wandb/sdk/wandb_run.py", line 1639, in _console_raw_callback
    self._backend.interface.publish_output_raw(name, data)
  File "/nfs/homes/sdreyer/.local/lib/python3.9/site-packages/wandb/sdk/interface/interface.py", line 762, in publish_output_raw
    self._publish_output_raw(o)
  File "/nfs/homes/sdreyer/.local/lib/python3.9/site-packages/wandb/sdk/interface/interface_shared.py", line 38, in _publish_output_raw
    self._publish(rec)
  File "/nfs/homes/sdreyer/.local/lib/python3.9/site-packages/wandb/sdk/interface/interface_sock.py", line 39, in _publish
    self._sock_client.send_record_publish(record)
  File "/nfs/homes/sdreyer/.local/lib/python3.9/site-packages/wandb/sdk/lib/sock_client.py", line 174, in send_record_publish
    self.send_server_request(server_req)
  File "/nfs/homes/sdreyer/.local/lib/python3.9/site-packages/wandb/sdk/lib/sock_client.py", line 154, in send_server_request
    self._send_message(msg)
  File "/nfs/homes/sdreyer/.local/lib/python3.9/site-packages/wandb/sdk/lib/sock_client.py", line 151, in _send_message
    self._sendall_with_error_handle(header + data)
  File "/nfs/homes/sdreyer/.local/lib/python3.9/site-packages/wandb/sdk/lib/sock_client.py", line 130, in _sendall_with_error_handle
    sent = self._sock.send(data)
BrokenPipeError: [Errno 32] Broken pipe
2025-05-14 16:01:36,233 ERROR   Thread-4  :1774956 [redirect.py:_on_write():664] [no run ID] error in stderr callback
Traceback (most recent call last):
  File "/nfs/homes/sdreyer/.local/lib/python3.9/site-packages/wandb/sdk/lib/redirect.py", line 662, in _on_write
    cb(written_data)
  File "/nfs/homes/sdreyer/.local/lib/python3.9/site-packages/wandb/sdk/wandb_run.py", line 2500, in <lambda>
    lambda data: self._console_raw_callback("stderr", data),
  File "/nfs/homes/sdreyer/.local/lib/python3.9/site-packages/wandb/sdk/wandb_run.py", line 406, in wrapper
    return func(self, *args, **kwargs)
  File "/nfs/homes/sdreyer/.local/lib/python3.9/site-packages/wandb/sdk/wandb_run.py", line 464, in wrapper_fn
    return func(self, *args, **kwargs)
  File "/nfs/homes/sdreyer/.local/lib/python3.9/site-packages/wandb/sdk/wandb_run.py", line 1639, in _console_raw_callback
    self._backend.interface.publish_output_raw(name, data)
  File "/nfs/homes/sdreyer/.local/lib/python3.9/site-packages/wandb/sdk/interface/interface.py", line 762, in publish_output_raw
    self._publish_output_raw(o)
  File "/nfs/homes/sdreyer/.local/lib/python3.9/site-packages/wandb/sdk/interface/interface_shared.py", line 38, in _publish_output_raw
    self._publish(rec)
  File "/nfs/homes/sdreyer/.local/lib/python3.9/site-packages/wandb/sdk/interface/interface_sock.py", line 39, in _publish
    self._sock_client.send_record_publish(record)
  File "/nfs/homes/sdreyer/.local/lib/python3.9/site-packages/wandb/sdk/lib/sock_client.py", line 174, in send_record_publish
    self.send_server_request(server_req)
  File "/nfs/homes/sdreyer/.local/lib/python3.9/site-packages/wandb/sdk/lib/sock_client.py", line 154, in send_server_request
    self._send_message(msg)
  File "/nfs/homes/sdreyer/.local/lib/python3.9/site-packages/wandb/sdk/lib/sock_client.py", line 151, in _send_message
    self._sendall_with_error_handle(header + data)
  File "/nfs/homes/sdreyer/.local/lib/python3.9/site-packages/wandb/sdk/lib/sock_client.py", line 130, in _sendall_with_error_handle
    sent = self._sock.send(data)
BrokenPipeError: [Errno 32] Broken pipe
2025-05-14 16:01:36,234 ERROR   Thread-4  :1774956 [redirect.py:_on_write():664] [no run ID] error in stderr callback
Traceback (most recent call last):
  File "/nfs/homes/sdreyer/.local/lib/python3.9/site-packages/wandb/sdk/lib/redirect.py", line 662, in _on_write
    cb(written_data)
  File "/nfs/homes/sdreyer/.local/lib/python3.9/site-packages/wandb/sdk/wandb_run.py", line 2500, in <lambda>
    lambda data: self._console_raw_callback("stderr", data),
  File "/nfs/homes/sdreyer/.local/lib/python3.9/site-packages/wandb/sdk/wandb_run.py", line 406, in wrapper
    return func(self, *args, **kwargs)
  File "/nfs/homes/sdreyer/.local/lib/python3.9/site-packages/wandb/sdk/wandb_run.py", line 464, in wrapper_fn
    return func(self, *args, **kwargs)
  File "/nfs/homes/sdreyer/.local/lib/python3.9/site-packages/wandb/sdk/wandb_run.py", line 1639, in _console_raw_callback
    self._backend.interface.publish_output_raw(name, data)
  File "/nfs/homes/sdreyer/.local/lib/python3.9/site-packages/wandb/sdk/interface/interface.py", line 762, in publish_output_raw
    self._publish_output_raw(o)
  File "/nfs/homes/sdreyer/.local/lib/python3.9/site-packages/wandb/sdk/interface/interface_shared.py", line 38, in _publish_output_raw
    self._publish(rec)
  File "/nfs/homes/sdreyer/.local/lib/python3.9/site-packages/wandb/sdk/interface/interface_sock.py", line 39, in _publish
    self._sock_client.send_record_publish(record)
  File "/nfs/homes/sdreyer/.local/lib/python3.9/site-packages/wandb/sdk/lib/sock_client.py", line 174, in send_record_publish
    self.send_server_request(server_req)
  File "/nfs/homes/sdreyer/.local/lib/python3.9/site-packages/wandb/sdk/lib/sock_client.py", line 154, in send_server_request
    self._send_message(msg)
  File "/nfs/homes/sdreyer/.local/lib/python3.9/site-packages/wandb/sdk/lib/sock_client.py", line 151, in _send_message
    self._sendall_with_error_handle(header + data)
  File "/nfs/homes/sdreyer/.local/lib/python3.9/site-packages/wandb/sdk/lib/sock_client.py", line 130, in _sendall_with_error_handle
    sent = self._sock.send(data)
BrokenPipeError: [Errno 32] Broken pipe
2025-05-14 16:01:36,245 ERROR   Thread-4  :1774956 [redirect.py:_on_write():664] [no run ID] error in stderr callback
Traceback (most recent call last):
  File "/nfs/homes/sdreyer/.local/lib/python3.9/site-packages/wandb/sdk/lib/redirect.py", line 662, in _on_write
    cb(written_data)
  File "/nfs/homes/sdreyer/.local/lib/python3.9/site-packages/wandb/sdk/wandb_run.py", line 2500, in <lambda>
    lambda data: self._console_raw_callback("stderr", data),
  File "/nfs/homes/sdreyer/.local/lib/python3.9/site-packages/wandb/sdk/wandb_run.py", line 406, in wrapper
    return func(self, *args, **kwargs)
  File "/nfs/homes/sdreyer/.local/lib/python3.9/site-packages/wandb/sdk/wandb_run.py", line 464, in wrapper_fn
    return func(self, *args, **kwargs)
  File "/nfs/homes/sdreyer/.local/lib/python3.9/site-packages/wandb/sdk/wandb_run.py", line 1639, in _console_raw_callback
    self._backend.interface.publish_output_raw(name, data)
  File "/nfs/homes/sdreyer/.local/lib/python3.9/site-packages/wandb/sdk/interface/interface.py", line 762, in publish_output_raw
    self._publish_output_raw(o)
  File "/nfs/homes/sdreyer/.local/lib/python3.9/site-packages/wandb/sdk/interface/interface_shared.py", line 38, in _publish_output_raw
    self._publish(rec)
  File "/nfs/homes/sdreyer/.local/lib/python3.9/site-packages/wandb/sdk/interface/interface_sock.py", line 39, in _publish
    self._sock_client.send_record_publish(record)
  File "/nfs/homes/sdreyer/.local/lib/python3.9/site-packages/wandb/sdk/lib/sock_client.py", line 174, in send_record_publish
    self.send_server_request(server_req)
  File "/nfs/homes/sdreyer/.local/lib/python3.9/site-packages/wandb/sdk/lib/sock_client.py", line 154, in send_server_request
    self._send_message(msg)
  File "/nfs/homes/sdreyer/.local/lib/python3.9/site-packages/wandb/sdk/lib/sock_client.py", line 151, in _send_message
    self._sendall_with_error_handle(header + data)
  File "/nfs/homes/sdreyer/.local/lib/python3.9/site-packages/wandb/sdk/lib/sock_client.py", line 130, in _sendall_with_error_handle
    sent = self._sock.send(data)
BrokenPipeError: [Errno 32] Broken pipe
2025-05-14 16:01:41,927 ERROR   MainThread:1774956 [redirect.py:_on_write():664] [no run ID] error in stderr callback
Traceback (most recent call last):
  File "/nfs/homes/sdreyer/.local/lib/python3.9/site-packages/wandb/agents/pyagent.py", line 219, in _run_jobs_from_queue
    thread.join()
  File "/usr/lib64/python3.9/threading.py", line 1060, in join
    self._wait_for_tstate_lock()
  File "/usr/lib64/python3.9/threading.py", line 1080, in _wait_for_tstate_lock
    if lock.acquire(block, timeout):
KeyboardInterrupt

During handling of the above exception, another exception occurred:

Traceback (most recent call last):
  File "/nfs/homes/sdreyer/.local/lib/python3.9/site-packages/wandb/sdk/lib/redirect.py", line 662, in _on_write
    cb(written_data)
  File "/nfs/homes/sdreyer/.local/lib/python3.9/site-packages/wandb/sdk/wandb_run.py", line 2500, in <lambda>
    lambda data: self._console_raw_callback("stderr", data),
  File "/nfs/homes/sdreyer/.local/lib/python3.9/site-packages/wandb/sdk/wandb_run.py", line 406, in wrapper
    return func(self, *args, **kwargs)
  File "/nfs/homes/sdreyer/.local/lib/python3.9/site-packages/wandb/sdk/wandb_run.py", line 464, in wrapper_fn
    return func(self, *args, **kwargs)
  File "/nfs/homes/sdreyer/.local/lib/python3.9/site-packages/wandb/sdk/wandb_run.py", line 1639, in _console_raw_callback
    self._backend.interface.publish_output_raw(name, data)
  File "/nfs/homes/sdreyer/.local/lib/python3.9/site-packages/wandb/sdk/interface/interface.py", line 762, in publish_output_raw
    self._publish_output_raw(o)
  File "/nfs/homes/sdreyer/.local/lib/python3.9/site-packages/wandb/sdk/interface/interface_shared.py", line 38, in _publish_output_raw
    self._publish(rec)
  File "/nfs/homes/sdreyer/.local/lib/python3.9/site-packages/wandb/sdk/interface/interface_sock.py", line 39, in _publish
    self._sock_client.send_record_publish(record)
  File "/nfs/homes/sdreyer/.local/lib/python3.9/site-packages/wandb/sdk/lib/sock_client.py", line 174, in send_record_publish
    self.send_server_request(server_req)
  File "/nfs/homes/sdreyer/.local/lib/python3.9/site-packages/wandb/sdk/lib/sock_client.py", line 154, in send_server_request
    self._send_message(msg)
  File "/nfs/homes/sdreyer/.local/lib/python3.9/site-packages/wandb/sdk/lib/sock_client.py", line 151, in _send_message
    self._sendall_with_error_handle(header + data)
  File "/nfs/homes/sdreyer/.local/lib/python3.9/site-packages/wandb/sdk/lib/sock_client.py", line 130, in _sendall_with_error_handle
    sent = self._sock.send(data)
BrokenPipeError: [Errno 32] Broken pipe
2025-05-14 16:01:42,157 INFO    MsgRouterThr:1774956 [mailbox.py:close():129] [no run ID] Closing mailbox, abandoning 1 handles.
